Workbook

Sheet Guide
B1: AHIM: Master Asset Register & Common Record
B2: Asset Health & Integrity Management · Lotus Africa Uranium Plant
B4: Purpose
B5: Every inspection input (vibration and visual routes, IR, substation, statutory, ultrasonic, oil analysis, diesel generator checklists, light vehicle and heavy equipment inspections and prestarts) is entered in ONE format against ONE asset list. The register and records then feed the AHIM dashboard: plant health, criticality, top priorities, open records and machine history.
B7: How it works
B8: Step | C8: What to do | D8: Who
B9: 1. Register the asset | C9: Add it to Asset_Register with its Pronto asset no., area, class, criticality factors and applicable techniques. ACI and class calculate automatically. | D9: RCM Specialist (once per asset)
B10: 2. Enter the result | C10: Each reading, checklist defect or certificate check becomes one row in Records. Pick the asset from the dropdown; description, area and ACI fill in. | D10: Input owner (analyst, electrician, DG operator, fleet mechanic, contractor)
B11: 3. Status is set | C11: Measured values: from the Alert/Danger limits. Checklists, visual, statutory: Inspector status using the severity rules below. | D11: Automatic / inspector
B12: 4. Priority and due date | C12: Alert and Danger rows get a priority score (ACI x severity), P1/P2/P3 and a due date automatically. Any Danger is always P1, whatever the asset criticality. | D12: Automatic
B13: 5. Action and close | C13: Raise the Pronto WO, enter the WO no., move the stage forward. Close only after a re-check confirms the fix, and record who verified it. | D13: RCM Specialist / planner
B14: 6. Review | C14: The asset's Current status in the register always shows the worst open record. Use filters on Records for overdue items. | D14: RCM Specialist (weekly)
B16: Colour legend
B17: Item | C17: Meaning
B18: Dark blue header | C18: Enter data in this column
B19: Grey header, grey cells | C19: Automatic formula: do not type over
B20: Blue italic text | C20: Sample data: replace or delete before go-live
B21: Blue on cream (Lists sheet) | C21: Settings: weights, thresholds, response times
B22: Red key cell (register) | C22: Duplicate Pronto asset no.
B23: Amber Record stage | C23: Alert/Danger row with no stage yet
B25: How each input source maps into the record
B26: Source (input) | C26: Technique(s) | D26: Record type | E26: How status is set | F26: Typical frequency | G26: Owner
B27: Vibration & visual route | C27: Vibration, Visual | D27: Measured + checklist | E27: Limits (ISO 20816-3: 4.5 / 7.1 mm/s); visual by severity rules | F27: Monthly route | G27: RCM Specialist
B28: IR survey | C28: Infrared | D28: Measured | E28: dT limits (NETA: >4 °C Alert, >15 °C Danger) or absolute temperature limits | F28: Monthly | G28: RCM Specialist
B29: Substation inspection | C29: Infrared, Visual, Electrical | D29: Measured + checklist | E29: Limits for readings; severity rules for checklist items | F29: Monthly | G29: Electrical
B30: Statutory inspection | C30: Statutory | D30: Compliance | E30: Inspector status; register also flags expiry (60 days = Alert, expired = Danger) | F30: Per certificate | G30: RCM Specialist / contractor
B31: Ultrasonic report | C31: Ultrasonic thickness, Ultrasonics (airborne) | D31: Measured | E31: Thickness: Lower is worse vs minimum wall. Airborne: dB limits | F31: Quarterly / annual | G31: UT contractor / RCM
B32: Oil analysis | C32: Lubrication / oil | D32: Measured | E32: Lab alarm limits per parameter (water, iron, silicon, viscosity...) | F32: Monthly / per service | G32: RCM Specialist
B33: DG checklist | C33: DG checks | D33: Measured | E33: Enter only the condition parameters (exhaust and turbo temperatures, oil pressure, coolant temperature, crankcase pressure) with limits | F33: Daily; enter weekly summary or any exceedance | G33: DG operator
B34: LV/HV inspection checklist | C34: Fleet inspection | D34: Checklist | E34: Severity rules per component | F34: Per service / monthly | G34: Fleet mechanic
B35: LV/HV prestart checklist | C35: Prestart | D35: Exceptions only | E35: Enter only defects found (severity rules); completion rate tracked separately | F35: Every shift | G35: Operator / supervisor
B37: Severity rules for checklists, visual and prestart items
B38: Status | C38: Definition | D38: Required response | E38: Examples
B39: OK | C39: Item within standard | D39: None (record only if part of a route) | E39: Guards fitted, no leaks
B40: Alert | C40: Defect, but safe to operate | D40: Repair within P2/P3 response time | E40: Minor oil leak, silica gel discoloured, worn seat, reverse alarm faulty
B41: Danger | C41: Unsafe or failure imminent | D41: Stop / isolate / tag out; repair before use (P1) | E41: Brakes or steering ineffective, seatbelt or fire suppression faulty, major leak, exposed live parts
B43: Asset numbering convention (site tag)
B44: Prefix | C44: Area | D44: Example
B45: AP- | C45: Acid plant | D45: AP-P-101 (pump), AP-TK-01 (tank)
B46: CK- | C46: Calciner | D46: CK-1080
...

Sheet Asset_Register
A1: AHIM Master Asset Register
A2: Dark headers = enter data. Grey headers = automatic (do not type). Blue italic rows are SAMPLES: replace with the Pronto asset list. Pronto asset no. is the unique key used everywhere.
L3: Criticality factors: 1 = low impact, 5 = severe | U3: Applicable techniques (enter Y)
A4: Pronto asset no. | B4: Site tag | C4: Description | D4: Area | E4: System / location | F4: Asset class | G4: Manufacturer | H4: Model | I4: Serial no. | J4: Operating mode | K4: Asset state | L4: Safety & env. (1-5) | M4: Production (1-5) | N4: Redundancy (1-5) | O4: Repair cost / MTTR (1-5) | P4: Failure history (1-5) | Q4: ACI (0-100) | R4: Class | S4: Current status | T4: Open records | U4: Vibration | V4: Lubrication / oil | W4: Ultrasonics (airborne) | X4: Ultrasonic thickness | Y4: Infrared | Z4: Visual | AA4: Statutory | AB4: Tank & vessel | AC4: Piping | AD4: Structural | AE4: Electrical | AF4: DG checks | AG4: Fleet inspection | AH4: Prestart | AI4: Statutory cert. required | AJ4: Certificate expiry | AK4: Days to expiry | AL4: Statutory status | AM4: Responsible | AN4: Remarks | AO4: Strategy class | AP4: Consequence (1-5) | AQ4: Service | AR4: Bottleneck (Y/N) | AS4: Replacement value (USD) | AT4: Consequence basis | AU4: Install year | AV4: Design life (years)
A5: 100101 | B5: AP-SF-01 | C5: Sulphur furnace | D5: Acid plant | E5: Gas generation | F5: Fired equipment | J5: Duty | K5: Active | L5: 5 | M5: 5 | N5: 5 | O5: 5 | P5: 2 | Q5: =IF(COUNT($L5:$P5)<5,"",ROUND(($L5*Lists!$M$2+$M5*Lists!$M$3+$N5*Lists!$M$4+$O5*Lists!$M$5+$P5*Lists!$M$6)/5*100,0)) -> 94 | R5: =IF($Q5="","",IF($Q5>=Lists!$M$20,"A",IF($Q5>=Lists!$M$21,"B","C"))) -> A | S5: =IF($A5="","",IF(COUNTIF(Records!$C$5:$C$3000,$A5)=0,"No data",CHOOSE(_xlfn.MAXIFS(Records!$R$5:$R$3000,Records!$C$5:$C$3000,$A5,Records!$Y$5:$Y$3000,"<>Closed")+1,"OK","Alert","Danger"))) -> Danger | T5: =IF($A5="","",COUNTIFS(Records!$C$5:$C$3000,$A5,Records!$R$5:$R$3000,">0",Records!$Y$5:$Y$3000,"<>Closed")) -> 1 | Y5: Y | Z5: Y | AA5: Y | AD5: Y | AI5: Y | AJ5: 46464 | AK5: =IF($AJ5="","",$AJ5-TODAY()) -> 164 | AL5: =IF($AJ5="","",IF($AK5<0,"Danger",IF($AK5<=Lists!$M$24,"Alert","OK"))) -> OK | AM5: Mechanical | AO5: Sulphur furnace / refractory-lined equipment | AP5: 5 | AS5: 6000000 | AT5: Default: criticality factors (safety and environment 5, production 5) | AU5: 2008 | AV5: 30
A6: 100102 | B6: AP-WHB-01 | C6: Waste heat boiler | D6: Acid plant | E6: Gas generation | F6: Boiler | J6: Duty | K6: Active | L6: 5 | M6: 5 | N6: 5 | O6: 4 | P6: 2 | Q6: =IF(COUNT($L6:$P6)<5,"",ROUND(($L6*Lists!$M$2+$M6*Lists!$M$3+$N6*Lists!$M$4+$O6*Lists!$M$5+$P6*Lists!$M$6)/5*100,0)) -> 91 | R6: =IF($Q6="","",IF($Q6>=Lists!$M$20,"A",IF($Q6>=Lists!$M$21,"B","C"))) -> A | S6: =IF($A6="","",IF(COUNTIF(Records!$C$5:$C$3000,$A6)=0,"No data",CHOOSE(_xlfn.MAXIFS(Records!$R$5:$R$3000,Records!$C$5:$C$3000,$A6,Records!$Y$5:$Y$3000,"<>Closed")+1,"OK","Alert","Danger"))) -> Alert | T6: =IF($A6="","",COUNTIFS(Records!$C$5:$C$3000,$A6,Records!$R$5:$R$3000,">0",Records!$Y$5:$Y$3000,"<>Closed")) -> 1 | W6: Y | X6: Y | Y6: Y | Z6: Y | AA6: Y | AB6: Y | AI6: Y | AJ6: 46317 | AK6: =IF($AJ6="","",$AJ6-TODAY()) -> 17 | AL6: =IF($AJ6="","",IF($AK6<0,"Danger",IF($AK6<=Lists!$M$24,"Alert","OK"))) -> Alert | AM6: Mechanical | AO6: Pressure vessel / boiler | AP6: 5 | AS6: 4500000 | AT6: Default: criticality factors (safety and environment 5, production 5) | AU6: 2008 | AV6: 25
A7: 100103 | B7: AP-BL-01 | C7: Main air blower | D7: Acid plant | E7: Gas generation | F7: Rotating - fan / blower | J7: Duty | K7: Active | L7: 4 | M7: 5 | N7: 5 | O7: 4 | P7: 3 | Q7: =IF(COUNT($L7:$P7)<5,"",ROUND(($L7*Lists!$M$2+$M7*Lists!$M$3+$N7*Lists!$M$4+$O7*Lists!$M$5+$P7*Lists!$M$6)/5*100,0)) -> 87 | R7: =IF($Q7="","",IF($Q7>=Lists!$M$20,"A",IF($Q7>=Lists!$M$21,"B","C"))) -> A | S7: =IF($A7="","",IF(COUNTIF(Records!$C$5:$C$3000,$A7)=0,"No data",CHOOSE(_xlfn.MAXIFS(Records!$R$5:$R$3000,Records!$C$5:$C$3000,$A7,Records!$Y$5:$Y$3000,"<>Closed")+1,"OK","Alert","Danger"))) -> Alert | T7: =IF($A7="","",COUNTIFS(Records!$C$5:$C$3000,$A7,Records!$R$5:$R$3000,">0",Records!$Y$5:$Y$3000,"<>Closed")) -> 1 | U7: Y | V7: Y | W7: Y | Y7: Y | Z7: Y | AE7: Y | AI7: N | AK7: =IF($AJ7="","",$AJ7-TODAY()) | AL7: =IF($AJ7="","",IF($AK7<0,"Danger",IF($AK7<=Lists!$M$24,"Alert","OK"))) | AM7: Mechanical | AO7: Fan / blower | AP7: 5 | AS7: 2200000 | AT7: Default: criticality factors (safety and environment 4, production 5) | AU7: 2008 | AV7: 25
A8: 100104 | B8: AP-CV-01 | C8: SO2 converter | D8: Acid plant | E8: Conversion | F8: Pressure vessel | J8: Duty | K8: Active | L8: 4 | M8: 5 | N8: 5 | O8: 5 | P8: 1 | Q8: =IF(COUNT($L8:$P8)<5,"",ROUND(($L8*Lists!$M$2+$M8*Lists!$M$3+$N8*Lists!$M$4+$O8*Lists!$M$5+$P8*Lists!$M$6)/5*100,0)) -> 86 | R8: =IF($Q8="","",IF($Q8>=Lists!$M$20,"A",IF($Q8>=Lists!$M$21,"B","C"))) -> A | S8: =IF($A8="","",IF(COUNTIF(Records!$C$5:$C$3000,$A8)=0,"No data",CHOOSE(_xlfn.MAXIFS(Records!$R$5:$R$3000,Records!$C$5:$C$3000,$A8,Records!$Y$5:$Y$3000,"<>Closed")+1,"OK","Alert","Danger"))) -> Alert | T8: =IF($A8="","",COUNTIFS(Records!$C$5:$C$3000,$A8,Records!$R$5:$R$3000,">0",Records!$Y$5:$Y$3000,"<>Closed")) -> 3 | Y8: Y | Z8: Y | AB8: Y | AD8: Y | AI8: N | AK8: =IF($AJ8="","",$AJ8-TODAY()) | AL8: =IF($AJ8="","",IF($AK8<0,"Danger",IF($AK8<=Lists!$M$24,"Alert","OK"))) | AM8: Mechanical | AO8: Pressure vessel / boiler | AP8: 5 | AS8: 5000000 | AT8: Default: criticality factors (safety and environment 4, production 5) | AU8: 2008 | AV8: 30
A9: 100105 | B9: AP-P-101 | C9: Drying tower acid pump | D9: Acid plant | E9: Drying & absorption | F9: Rotating - pump | J9: Duty | K9: Active | L9: 4 | M9: 4 | N9: 3 | O9: 3 | P9: 4 | Q9: =IF(COUNT($L9:$P9)<5,"",ROUND(($L9*Lists!$M$2+$M9*Lists!$M$3+$N9*Lists!$M$4+$O9*Lists!$M$5+$P9*Lists!$M$6)/5*100,0)) -> 74 | R9: =IF($Q9="","",IF($Q9>=Lists!$M$20,"A",IF($Q9>=Lists!$M$21,"B","C"))) -> A | S9: =IF($A9="","",IF(COUNTIF(Records!$C$5:$C$3000,$A9)=0,"No data",CHOOSE(_xlfn.MAXIFS(Records!$R$5:$R$3000,Records!$C$5:$C$3000,$A9,Records!$Y$5:$Y$3000,"<>Closed")+1,"OK","Alert","Danger"))) -> Danger | T9: =IF($A9="","",COUNTIFS(Records!$C$5:$C$3000,$A9,Records!$R$5:$R$3000,">0",Records!$Y$5:$Y$3000,"<>Closed")) -> 2 | U9: Y | V9: Y | W9: Y | Y9: Y | Z9: Y | AE9: Y | AI9: N | AK9: =IF($AJ9="","",$AJ9-TODAY()) | AL9: =IF($AJ9="","",IF($AK9<0,"Danger",IF($AK9<=Lists!$M$24,"Alert","OK"))) | AM9: Mechanical | AO9: Centrifugal process pump | AP9: 4 | AS9: 180000 | AT9: Default: criticality factors (safety and environment 4, production 4) | AU9: 2012 | AV9: 15
A10: 100106 | B10: AP-P-102 | C10: Interpass tower acid pump | D10: Acid plant | E10: Drying & absorption | F10: Rotating - pump | J10: Duty | K10: Active | L10: 4 | M10: 5 | N10: 3 | O10: 3 | P10: 2 | Q10: =IF(COUNT($L10:$P10)<5,"",ROUND(($L10*Lists!$M$2+$M10*Lists!$M$3+$N10*Lists!$M$4+$O10*Lists!$M$5+$P10*Lists!$M$6)/5*100,0)) -> 76 | R10: =IF($Q10="","",IF($Q10>=Lists!$M$20,"A",IF($Q10>=Lists!$M$21,"B","C"))) -> A | S10: =IF($A10="","",IF(COUNTIF(Records!$C$5:$C$3000,$A10)=0,"No data",CHOOSE(_xlfn.MAXIFS(Records!$R$5:$R$3000,Records!$C$5:$C$3000,$A10,Records!$Y$5:$Y$3000,"<>Closed")+1,"OK","Alert","Danger"))) -> OK | T10: =IF($A10="","",COUNTIFS(Records!$C$5:$C$3000,$A10,Records!$R$5:$R$3000,">0",Records!$Y$5:$Y$3000,"<>Closed")) -> 0 | U10: Y | V10: Y | W10: Y | Y10: Y | Z10: Y | AE10: Y | AI10: N | AK10: =IF($AJ10="","",$AJ10-TODAY()) | AL10: =IF($AJ10="","",IF($AK10<0,"Danger",IF($AK10<=Lists!$M$24,"Alert","OK"))) | AM10: Mechanical | AO10: Centrifugal process pump | AP10: 5 | AS10: 180000 | AT10: Default: criticality factors (safety and environment 4, production 5) | AU10: 2012 | AV10: 15
A11: 100107 | B11: AP-P-103 | C11: Final tower acid pump | D11: Acid plant | E11: Drying & absorption | F11: Rotating - pump | J11: Duty | K11: Active | L11: 3 | M11: 4 | N11: 3 | O11: 3 | P11: 3 | Q11: =IF(COUNT($L11:$P11)<5,"",ROUND(($L11*Lists!$M$2+$M11*Lists!$M$3+$N11*Lists!$M$4+$O11*Lists!$M$5+$P11*Lists!$M$6)/5*100,0)) -> 66 | R11: =IF($Q11="","",IF($Q11>=Lists!$M$20,"A",IF($Q11>=Lists!$M$21,"B","C"))) -> B | S11: =IF($A11="","",IF(COUNTIF(Records!$C$5:$C$3000,$A11)=0,"No data",CHOOSE(_xlfn.MAXIFS(Records!$R$5:$R$3000,Records!$C$5:$C$3000,$A11,Records!$Y$5:$Y$3000,"<>Closed")+1,"OK","Alert","Danger"))) -> Alert | T11: =IF($A11="","",COUNTIFS(Records!$C$5:$C$3000,$A11,Records!$R$5:$R$3000,">0",Records!$Y$5:$Y$3000,"<>Closed")) -> 5 | U11: Y | V11: Y | W11: Y | Y11: Y | Z11: Y | AE11: Y | AI11: N | AK11: =IF($AJ11="","",$AJ11-TODAY()) | AL11: =IF($AJ11="","",IF($AK11<0,"Danger",IF($AK11<=Lists!$M$24,"Alert","OK"))) | AM11: Mechanical | AO11: Centrifugal process pump | AP11: 4 | AS11: 160000 | AT11: Default: criticality factors (safety and environment 3, production 4) | AU11: 2009 | AV11: 15
A12: 100108 | B12: AP-P-201 | C12: Boiler feed water pump A | D12: Acid plant | E12: Steam system | F12: Rotating - pump | J12: Duty | K12: Active | L12: 4 | M12: 5 | N12: 2 | O12: 3 | P12: 3 | Q12: =IF(COUNT($L12:$P12)<5,"",ROUND(($L12*Lists!$M$2+$M12*Lists!$M$3+$N12*Lists!$M$4+$O12*Lists!$M$5+$P12*Lists!$M$6)/5*100,0)) -> 75 | R12: =IF($Q12="","",IF($Q12>=Lists!$M$20,"A",IF($Q12>=Lists!$M$21,"B","C"))) -> A | S12: =IF($A12="","",IF(COUNTIF(Records!$C$5:$C$3000,$A12)=0,"No data",CHOOSE(_xlfn.MAXIFS(Records!$R$5:$R$3000,Records!$C$5:$C$3000,$A12,Records!$Y$5:$Y$3000,"<>Closed")+1,"OK","Alert","Danger"))) -> Alert | T12: =IF($A12="","",COUNTIFS(Records!$C$5:$C$3000,$A12,Records!$R$5:$R$3000,">0",Records!$Y$5:$Y$3000,"<>Closed")) -> 1 | U12: Y | V12: Y | W12: Y | Y12: Y | Z12: Y | AE12: Y | AI12: N | AK12: =IF($AJ12="","",$AJ12-TODAY()) | AL12: =IF($AJ12="","",IF($AK12<0,"Danger",IF($AK12<=Lists!$M$24,"Alert","OK"))) | AM12: Mechanical | AO12: Centrifugal process pump | AP12: 5 | AS12: 140000 | AT12: Default: criticality factors (safety and environment 4, production 5) | AU12: 2010 | AV12: 20
A13: 100109 | B13: AP-P-202 | C13: Boiler feed water pump B | D13: Acid plant | E13: Steam system | F13: Rotating - pump | J13: Standby | K13: Active | L13: 4 | M13: 5 | N13: 2 | O13: 3 | P13: 1 | Q13: =IF(COUNT($L13:$P13)<5,"",ROUND(($L13*Lists!$M$2+$M13*Lists!$M$3+$N13*Lists!$M$4+$O13*Lists!$M$5+$P13*Lists!$M$6)/5*100,0)) -> 71 | R13: =IF($Q13="","",IF($Q13>=Lists!$M$20,"A",IF($Q13>=Lists!$M$21,"B","C"))) -> A | S13: =IF($A13="","",IF(COUNTIF(Records!$C$5:$C$3000,$A13)=0,"No data",CHOOSE(_xlfn.MAXIFS(Records!$R$5:$R$3000,Records!$C$5:$C$3000,$A13,Records!$Y$5:$Y$3000,"<>Closed")+1,"OK","Alert","Danger"))) -> OK | T13: =IF($A13="","",COUNTIFS(Records!$C$5:$C$3000,$A13,Records!$R$5:$R$3000,">0",Records!$Y$5:$Y$3000,"<>Closed")) -> 0 | U13: Y | V13: Y | W13: Y | Y13: Y | Z13: Y | AE13: Y | AI13: N | AK13: =IF($AJ13="","",$AJ13-TODAY()) | AL13: =IF($AJ13="","",IF($AK13<0,"Danger",IF($AK13<=Lists!$M$24,"Alert","OK"))) | AM13: Mechanical | AO13: Centrifugal process pump | AP13: 5 | AS13: 140000 | AT13: Default: criticality factors (safety and environment 4, production 5) | AU13: 2010 | AV13: 20
A14: 100110 | B14: AP-P-301 | C14: Molten sulphur pump | D14: Acid plant | E14: Sulphur handling | F14: Rotating - pump | J14: Duty | K14: Active | L14: 3 | M14: 4 | N14: 3 | O14: 2 | P14: 2 | Q14: =IF(COUNT($L14:$P14)<5,"",ROUND(($L14*Lists!$M$2+$M14*Lists!$M$3+$N14*Lists!$M$4+$O14*Lists!$M$5+$P14*Lists!$M$6)/5*100,0)) -> 61 | R14: =IF($Q14="","",IF($Q14>=Lists!$M$20,"A",IF($Q14>=Lists!$M$21,"B","C"))) -> B | S14: =IF($A14="","",IF(COUNTIF(Records!$C$5:$C$3000,$A14)=0,"No data",CHOOSE(_xlfn.MAXIFS(Records!$R$5:$R$3000,Records!$C$5:$C$3000,$A14,Records!$Y$5:$Y$3000,"<>Closed")+1,"OK","Alert","Danger"))) -> OK | T14: =IF($A14="","",COUNTIFS(Records!$C$5:$C$3000,$A14,Records!$R$5:$R$3000,">0",Records!$Y$5:$Y$3000,"<>Closed")) -> 0 | U14: Y | V14: Y | W14: Y | Y14: Y | Z14: Y | AI14: N | AK14: =IF($AJ14="","",$AJ14-TODAY()) | AL14: =IF($AJ14="","",IF($AK14<0,"Danger",IF($AK14<=Lists!$M$24,"Alert","OK"))) | AM14: Mechanical | AO14: Centrifugal process pump | AP14: 4 | AS14: 120000 | AT14: Default: criticality factors (safety and environment 3, production 4) | AU14: 2008 | AV14: 20
A15: 100111 | B15: AP-AG-01 | C15: Sulphur melter agitator | D15: Acid plant | E15: Sulphur handling | F15: Rotating - agitator | J15: Duty | K15: Active | L15: 2 | M15: 2 | N15: 3 | O15: 2 | P15: 2 | Q15: =IF(COUNT($L15:$P15)<5,"",ROUND(($L15*Lists!$M$2+$M15*Lists!$M$3+$N15*Lists!$M$4+$O15*Lists!$M$5+$P15*Lists!$M$6)/5*100,0)) -> 43 | R15: =IF($Q15="","",IF($Q15>=Lists!$M$20,"A",IF($Q15>=Lists!$M$21,"B","C"))) -> C | S15: =IF($A15="","",IF(COUNTIF(Records!$C$5:$C$3000,$A15)=0,"No data",CHOOSE(_xlfn.MAXIFS(Records!$R$5:$R$3000,Records!$C$5:$C$3000,$A15,Records!$Y$5:$Y$3000,"<>Closed")+1,"OK","Alert","Danger"))) -> OK | T15: =IF($A15="","",COUNTIFS(Records!$C$5:$C$3000,$A15,Records!$R$5:$R$3000,">0",Records!$Y$5:$Y$3000,"<>Closed")) -> 0 | U15: Y | V15: Y | Z15: Y | AI15: N | AK15: =IF($AJ15="","",$AJ15-TODAY()) | AL15: =IF($AJ15="","",IF($AK15<0,"Danger",IF($AK15<=Lists!$M$24,"Alert","OK"))) | AM15: Mechanical | AO15: Agitator | AP15: 2 | AS15: 90000 | AT15: Default: criticality factors (safety and environment 2, production 2) | AU15: 2008 | AV15: 20
A16: 100112 | B16: AP-CT-01 | C16: Cooling tower fan 1 | D16: Acid plant | E16: Cooling water | F16: Rotating - gearbox / drive | J16: Duty | K16: Active | L16: 2 | M16: 3 | N16: 2 | O16: 2 | P16: 4 | Q16: =IF(COUNT($L16:$P16)<5,"",ROUND(($L16*Lists!$M$2+$M16*Lists!$M$3+$N16*Lists!$M$4+$O16*Lists!$M$5+$P16*Lists!$M$6)/5*100,0)) -> 50 | R16: =IF($Q16="","",IF($Q16>=Lists!$M$20,"A",IF($Q16>=Lists!$M$21,"B","C"))) -> B | S16: =IF($A16="","",IF(COUNTIF(Records!$C$5:$C$3000,$A16)=0,"No data",CHOOSE(_xlfn.MAXIFS(Records!$R$5:$R$3000,Records!$C$5:$C$3000,$A16,Records!$Y$5:$Y$3000,"<>Closed")+1,"OK","Alert","Danger"))) -> Alert | T16: =IF($A16="","",COUNTIFS(Records!$C$5:$C$3000,$A16,Records!$R$5:$R$3000,">0",Records!$Y$5:$Y$3000,"<>Closed")) -> 10 | U16: Y | V16: Y | Z16: Y | AD16: Y | AE16: Y | AI16: N | AK16: =IF($AJ16="","",$AJ16-TODAY()) | AL16: =IF($AJ16="","",IF($AK16<0,"Danger",IF($AK16<=Lists!$M$24,"Alert","OK"))) | AM16: Mechanical | AO16: Gearbox (stand-alone) | AP16: 3 | AS16: 350000 | AT16: Default: criticality factors (safety and environment 2, production 3) | AU16: 2008 | AV16: 20
A17: 100113 | B17: AP-TK-01 | C17: Product acid storage tank | D17: Acid plant | E17: Product storage | F17: Tank | J17: Duty | K17: Active | L17: 5 | M17: 3 | N17: 4 | O17: 4 | P17: 2 | Q17: =IF(COUNT($L17:$P17)<5,"",ROUND(($L17*Lists!$M$2+$M17*Lists!$M$3+$N17*Lists!$M$4+$O17*Lists!$M$5+$P17*Lists!$M$6)/5*100,0)) -> 76 | R17: =IF($Q17="","",IF($Q17>=Lists!$M$20,"A",IF($Q17>=Lists!$M$21,"B","C"))) -> A | S17: =IF($A17="","",IF(COUNTIF(Records!$C$5:$C$3000,$A17)=0,"No data",CHOOSE(_xlfn.MAXIFS(Records!$R$5:$R$3000,Records!$C$5:$C$3000,$A17,Records!$Y$5:$Y$3000,"<>Closed")+1,"OK","Alert","Danger"))) -> Alert | T17: =IF($A17="","",COUNTIFS(Records!$C$5:$C$3000,$A17,Records!$R$5:$R$3000,">0",Records!$Y$5:$Y$3000,"<>Closed")) -> 2 | X17: Y | Z17: Y | AA17: Y | AB17: Y | AD17: Y | AI17: Y | AJ17: 46479 | AK17: =IF($AJ17="","",$AJ17-TODAY()) -> 179 | AL17: =IF($AJ17="","",IF($AK17<0,"Danger",IF($AK17<=Lists!$M$24,"Alert","OK"))) -> OK | AM17: Mechanical | AO17: Atmospheric storage tank | AP17: 5 | AS17: 1200000 | AT17: Default: criticality factors (safety and environment 5, production 3) | AU17: 2008 | AV17: 25
A18: 100114 | B18: AP-PL-01 | C18: Acid transfer line | D18: Acid plant | E18: Product storage | F18: Piping | J18: Duty | K18: Active | L18: 5 | M18: 4 | N18: 5 | O18: 2 | P18: 3 | Q18: =IF(COUNT($L18:$P18)<5,"",ROUND(($L18*Lists!$M$2+$M18*Lists!$M$3+$N18*Lists!$M$4+$O18*Lists!$M$5+$P18*Lists!$M$6)/5*100,0)) -> 81 | R18: =IF($Q18="","",IF($Q18>=Lists!$M$20,"A",IF($Q18>=Lists!$M$21,"B","C"))) -> A | S18: =IF($A18="","",IF(COUNTIF(Records!$C$5:$C$3000,$A18)=0,"No data",CHOOSE(_xlfn.MAXIFS(Records!$R$5:$R$3000,Records!$C$5:$C$3000,$A18,Records!$Y$5:$Y$3000,"<>Closed")+1,"OK","Alert","Danger"))) -> Danger | T18: =IF($A18="","",COUNTIFS(Records!$C$5:$C$3000,$A18,Records!$R$5:$R$3000,">0",Records!$Y$5:$Y$3000,"<>Closed")) -> 1 | X18: Y | Z18: Y | AC18: Y | AI18: N | AK18: =IF($AJ18="","",$AJ18-TODAY()) | AL18: =IF($AJ18="","",IF($AK18<0,"Danger",IF($AK18<=Lists!$M$24,"Alert","OK"))) | AM18: Mechanical | AO18: Piping (acid / slurry / process) | AP18: 5 | AS18: 300000 | AT18: Default: criticality factors (safety and environment 5, production 4) | AU18: 2011 | AV18: 15
A19: 100115 | B19: AP-AR-01 | C19: Instrument air receiver | D19: Acid plant | E19: Utilities air | F19: Pressure vessel | J19: Duty | K19: Active | L19: 4 | M19: 2 | N19: 3 | O19: 2 | P19: 1 | Q19: =IF(COUNT($L19:$P19)<5,"",ROUND(($L19*Lists!$M$2+$M19*Lists!$M$3+$N19*Lists!$M$4+$O19*Lists!$M$5+$P19*Lists!$M$6)/5*100,0)) -> 53 | R19: =IF($Q19="","",IF($Q19>=Lists!$M$20,"A",IF($Q19>=Lists!$M$21,"B","C"))) -> B | S19: =IF($A19="","",IF(COUNTIF(Records!$C$5:$C$3000,$A19)=0,"No data",CHOOSE(_xlfn.MAXIFS(Records!$R$5:$R$3000,Records!$C$5:$C$3000,$A19,Records!$Y$5:$Y$3000,"<>Closed")+1,"OK","Alert","Danger"))) -> OK | T19: =IF($A19="","",COUNTIFS(Records!$C$5:$C$3000,$A19,Records!$R$5:$R$3000,">0",Records!$Y$5:$Y$3000,"<>Closed")) -> 0 | W19: Y | Z19: Y | AA19: Y | AB19: Y | AI19: Y | AJ19: 46458 | AK19: =IF($AJ19="","",$AJ19-TODAY()) -> 158 | AL19: =IF($AJ19="","",IF($AK19<0,"Danger",IF($AK19<=Lists!$M$24,"Alert","OK"))) -> OK | AM19: Mechanical | AO19: Pressure vessel / boiler | AP19: 4 | AS19: 80000 | AT19: Default: criticality factors (safety and environment 4, production 2) | AU19: 2008 | AV19: 30
A20: 100201 | B20: CK-1080 | C20: Calciner kiln 1080 | D20: Calciner | E20: Calcining | F20: Rotary kiln | J20: Duty | K20: Active | L20: 4 | M20: 5 | N20: 5 | O20: 5 | P20: 3 | Q20: =IF(COUNT($L20:$P20)<5,"",ROUND(($L20*Lists!$M$2+$M20*Lists!$M$3+$N20*Lists!$M$4+$O20*Lists!$M$5+$P20*Lists!$M$6)/5*100,0)) -> 90 | R20: =IF($Q20="","",IF($Q20>=Lists!$M$20,"A",IF($Q20>=Lists!$M$21,"B","C"))) -> A | S20: =IF($A20="","",IF(COUNTIF(Records!$C$5:$C$3000,$A20)=0,"No data",CHOOSE(_xlfn.MAXIFS(Records!$R$5:$R$3000,Records!$C$5:$C$3000,$A20,Records!$Y$5:$Y$3000,"<>Closed")+1,"OK","Alert","Danger"))) -> Alert | T20: =IF($A20="","",COUNTIFS(Records!$C$5:$C$3000,$A20,Records!$R$5:$R$3000,">0",Records!$Y$5:$Y$3000,"<>Closed")) -> 2 | U20: Y | V20: Y | Y20: Y | Z20: Y | AD20: Y | AI20: N | AK20: =IF($AJ20="","",$AJ20-TODAY()) | AL20: =IF($AJ20="","",IF($AK20<0,"Danger",IF($AK20<=Lists!$M$24,"Alert","OK"))) | AM20: Mechanical | AO20: Rotary dryer / kiln / calciner | AP20: 5 | AS20: 12000000 | AT20: Default: criticality factors (safety and environment 4, production 5) | AU20: 2009 | AV20: 30
A21: 100301 | B21: SS-TX-01 | C21: Transformer TX-01 | D21: Substation | E21: Main substation | F21: Electrical - transformer | J21: Duty | K21: Active | L21: 4 | M21: 5 | N21: 5 | O21: 5 | P21: 1 | Q21: =IF(COUNT($L21:$P21)<5,"",ROUND(($L21*Lists!$M$2+$M21*Lists!$M$3+$N21*Lists!$M$4+$O21*Lists!$M$5+$P21*Lists!$M$6)/5*100,0)) -> 86 | R21: =IF($Q21="","",IF($Q21>=Lists!$M$20,"A",IF($Q21>=Lists!$M$21,"B","C"))) -> A | S21: =IF($A21="","",IF(COUNTIF(Records!$C$5:$C$3000,$A21)=0,"No data",CHOOSE(_xlfn.MAXIFS(Records!$R$5:$R$3000,Records!$C$5:$C$3000,$A21,Records!$Y$5:$Y$3000,"<>Closed")+1,"OK","Alert","Danger"))) -> Alert | T21: =IF($A21="","",COUNTIFS(Records!$C$5:$C$3000,$A21,Records!$R$5:$R$3000,">0",Records!$Y$5:$Y$3000,"<>Closed")) -> 4 | V21: Y | W21: Y | Y21: Y | Z21: Y | AE21: Y | AI21: N | AK21: =IF($AJ21="","",$AJ21-TODAY()) | AL21: =IF($AJ21="","",IF($AK21<0,"Danger",IF($AK21<=Lists!$M$24,"Alert","OK"))) | AM21: Electrical | AO21: Switchgear / MCC / transformer | AP21: 5 | AS21: 1500000 | AT21: Default: criticality factors (safety and environment 4, production 5) | AU21: 2008 | AV21: 35
A22: 100302 | B22: SS-MCC-01 | C22: Acid plant MCC | D22: Substation | E22: Main substation | F22: Electrical - switchgear / MCC | J22: Duty | K22: Active | L22: 4 | M22: 5 | N22: 5 | O22: 3 | P22: 2 | Q22: =IF(COUNT($L22:$P22)<5,"",ROUND(($L22*Lists!$M$2+$M22*Lists!$M$3+$N22*Lists!$M$4+$O22*Lists!$M$5+$P22*Lists!$M$6)/5*100,0)) -> 82 | R22: =IF($Q22="","",IF($Q22>=Lists!$M$20,"A",IF($Q22>=Lists!$M$21,"B","C"))) -> A | S22: =IF($A22="","",IF(COUNTIF(Records!$C$5:$C$3000,$A22)=0,"No data",CHOOSE(_xlfn.MAXIFS(Records!$R$5:$R$3000,Records!$C$5:$C$3000,$A22,Records!$Y$5:$Y$3000,"<>Closed")+1,"OK","Alert","Danger"))) -> Danger | T22: =IF($A22="","",COUNTIFS(Records!$C$5:$C$3000,$A22,Records!$R$5:$R$3000,">0",Records!$Y$5:$Y$3000,"<>Closed")) -> 2 | W22: Y | Y22: Y | Z22: Y | AE22: Y | AI22: N | AK22: =IF($AJ22="","",$AJ22-TODAY()) | AL22: =IF($AJ22="","",IF($AK22<0,"Danger",IF($AK22<=Lists!$M$24,"Alert","OK"))) | AM22: Electrical | AO22: Switchgear / MCC / transformer | AP22: 5 | AS22: 600000 | AT22: Default: criticality factors (safety and environment 4, production 5) | AU22: 2008 | AV22: 25
A23: 100401 | B23: PP-GEN-01 | C23: Diesel generator Gen 1 | D23: Power plant | E23: Power station | F23: Diesel generator | G23: Hyundai | J23: Duty | K23: Active | L23: 4 | M23: 5 | N23: 3 | O23: 4 | P23: 4 | Q23: =IF(COUNT($L23:$P23)<5,"",ROUND(($L23*Lists!$M$2+$M23*Lists!$M$3+$N23*Lists!$M$4+$O23*Lists!$M$5+$P23*Lists!$M$6)/5*100,0)) -> 83 | R23: =IF($Q23="","",IF($Q23>=Lists!$M$20,"A",IF($Q23>=Lists!$M$21,"B","C"))) -> A | S23: =IF($A23="","",IF(COUNTIF(Records!$C$5:$C$3000,$A23)=0,"No data",CHOOSE(_xlfn.MAXIFS(Records!$R$5:$R$3000,Records!$C$5:$C$3000,$A23,Records!$Y$5:$Y$3000,"<>Closed")+1,"OK","Alert","Danger"))) -> Alert | T23: =IF($A23="","",COUNTIFS(Records!$C$5:$C$3000,$A23,Records!$R$5:$R$3000,">0",Records!$Y$5:$Y$3000,"<>Closed")) -> 1 | U23: Y | V23: Y | Y23: Y | Z23: Y | AE23: Y | AF23: Y | AI23: N | AK23: =IF($AJ23="","",$AJ23-TODAY()) | AL23: =IF($AJ23="","",IF($AK23<0,"Danger",IF($AK23<=Lists!$M$24,"Alert","OK"))) | AM23: Power plant | AO23: Diesel generator | AP23: 5 | AS23: 1800000 | AT23: Default: criticality factors (safety and environment 4, production 5) | AU23: 2010 | AV23: 20
A24: 100402 | B24: PP-GEN-02 | C24: Diesel generator Gen 2 | D24: Power plant | E24: Power station | F24: Diesel generator | G24: Hyundai | J24: Duty | K24: Active | L24: 4 | M24: 5 | N24: 3 | O24: 4 | P24: 2 | Q24: =IF(COUNT($L24:$P24)<5,"",ROUND(($L24*Lists!$M$2+$M24*Lists!$M$3+$N24*Lists!$M$4+$O24*Lists!$M$5+$P24*Lists!$M$6)/5*100,0)) -> 79 | R24: =IF($Q24="","",IF($Q24>=Lists!$M$20,"A",IF($Q24>=Lists!$M$21,"B","C"))) -> A | S24: =IF($A24="","",IF(COUNTIF(Records!$C$5:$C$3000,$A24)=0,"No data",CHOOSE(_xlfn.MAXIFS(Records!$R$5:$R$3000,Records!$C$5:$C$3000,$A24,Records!$Y$5:$Y$3000,"<>Closed")+1,"OK","Alert","Danger"))) -> OK | T24: =IF($A24="","",COUNTIFS(Records!$C$5:$C$3000,$A24,Records!$R$5:$R$3000,">0",Records!$Y$5:$Y$3000,"<>Closed")) -> 0 | U24: Y | V24: Y | Y24: Y | Z24: Y | AE24: Y | AF24: Y | AI24: N | AK24: =IF($AJ24="","",$AJ24-TODAY()) | AL24: =IF($AJ24="","",IF($AK24<0,"Danger",IF($AK24<=Lists!$M$24,"Alert","OK"))) | AM24: Power plant | AO24: Diesel generator | AP24: 5 | AS24: 1800000 | AT24: Default: criticality factors (safety and environment 4, production 5) | AU24: 2010 | AV24: 20
A25: 100403 | B25: PP-GEN-03 | C25: Diesel generator Gen 3 | D25: Power plant | E25: Power station | F25: Diesel generator | G25: Hyundai | J25: Standby | K25: Active | L25: 4 | M25: 5 | N25: 3 | O25: 4 | P25: 2 | Q25: =IF(COUNT($L25:$P25)<5,"",ROUND(($L25*Lists!$M$2+$M25*Lists!$M$3+$N25*Lists!$M$4+$O25*Lists!$M$5+$P25*Lists!$M$6)/5*100,0)) -> 79 | R25: =IF($Q25="","",IF($Q25>=Lists!$M$20,"A",IF($Q25>=Lists!$M$21,"B","C"))) -> A | S25: =IF($A25="","",IF(COUNTIF(Records!$C$5:$C$3000,$A25)=0,"No data",CHOOSE(_xlfn.MAXIFS(Records!$R$5:$R$3000,Records!$C$5:$C$3000,$A25,Records!$Y$5:$Y$3000,"<>Closed")+1,"OK","Alert","Danger"))) -> OK | T25: =IF($A25="","",COUNTIFS(Records!$C$5:$C$3000,$A25,Records!$R$5:$R$3000,">0",Records!$Y$5:$Y$3000,"<>Closed")) -> 0 | U25: Y | V25: Y | Y25: Y | Z25: Y | AE25: Y | AF25: Y | AI25: N | AK25: =IF($AJ25="","",$AJ25-TODAY()) | AL25: =IF($AJ25="","",IF($AK25<0,"Danger",IF($AK25<=Lists!$M$24,"Alert","OK"))) | AM25: Power plant | AO25: Diesel generator | AP25: 5 | AS25: 1800000 | AT25: Default: criticality factors (safety and environment 4, production 5) | AU25: 2010 | AV25: 20
A26: 100404 | B26: PP-GEN-04 | C26: Diesel generator Gen 4 | D26: Power plant | E26: Power station | F26: Diesel generator | G26: Hyundai | J26: Duty | K26: Active | L26: 5 | M26: 5 | N26: 3 | O26: 5 | P26: 4 | Q26: =IF(COUNT($L26:$P26)<5,"",ROUND(($L26*Lists!$M$2+$M26*Lists!$M$3+$N26*Lists!$M$4+$O26*Lists!$M$5+$P26*Lists!$M$6)/5*100,0)) -> 92 | R26: =IF($Q26="","",IF($Q26>=Lists!$M$20,"A",IF($Q26>=Lists!$M$21,"B","C"))) -> A | S26: =IF($A26="","",IF(COUNTIF(Records!$C$5:$C$3000,$A26)=0,"No data",CHOOSE(_xlfn.MAXIFS(Records!$R$5:$R$3000,Records!$C$5:$C$3000,$A26,Records!$Y$5:$Y$3000,"<>Closed")+1,"OK","Alert","Danger"))) -> Alert | T26: =IF($A26="","",COUNTIFS(Records!$C$5:$C$3000,$A26,Records!$R$5:$R$3000,">0",Records!$Y$5:$Y$3000,"<>Closed")) -> 1 | U26: Y | V26: Y | Y26: Y | Z26: Y | AE26: Y | AF26: Y | AI26: N | AK26: =IF($AJ26="","",$AJ26-TODAY()) | AL26: =IF($AJ26="","",IF($AK26<0,"Danger",IF($AK26<=Lists!$M$24,"Alert","OK"))) | AM26: Power plant | AO26: Diesel generator | AP26: 5 | AS26: 1800000 | AT26: Default: criticality factors (safety and environment 5, production 5) | AU26: 2010 | AV26: 20
A27: 100501 | B27: LV-01 | C27: Light vehicle LV-01 (pickup) | D27: Mobile fleet | E27: Light vehicles | F27: Light vehicle | J27: Mobile | K27: Active | L27: 3 | M27: 2 | N27: 2 | O27: 1 | P27: 2 | Q27: =IF(COUNT($L27:$P27)<5,"",ROUND(($L27*Lists!$M$2+$M27*Lists!$M$3+$N27*Lists!$M$4+$O27*Lists!$M$5+$P27*Lists!$M$6)/5*100,0)) -> 43 | R27: =IF($Q27="","",IF($Q27>=Lists!$M$20,"A",IF($Q27>=Lists!$M$21,"B","C"))) -> C | S27: =IF($A27="","",IF(COUNTIF(Records!$C$5:$C$3000,$A27)=0,"No data",CHOOSE(_xlfn.MAXIFS(Records!$R$5:$R$3000,Records!$C$5:$C$3000,$A27,Records!$Y$5:$Y$3000,"<>Closed")+1,"OK","Alert","Danger"))) -> Alert | T27: =IF($A27="","",COUNTIFS(Records!$C$5:$C$3000,$A27,Records!$R$5:$R$3000,">0",Records!$Y$5:$Y$3000,"<>Closed")) -> 1 | V27: Y | Z27: Y | AG27: Y | AH27: Y | AI27: N | AK27: =IF($AJ27="","",$AJ27-TODAY()) | AL27: =IF($AJ27="","",IF($AK27<0,"Danger",IF($AK27<=Lists!$M$24,"Alert","OK"))) | AM27: Fleet workshop | AP27: 3 | AS27: 60000 | AT27: Default: criticality factors (safety and environment 3, production 2) | AU27: 2021 | AV27: 6
A28: 100502 | B28: LV-02 | C28: Light vehicle LV-02 (pickup) | D28: Mobile fleet | E28: Light vehicles | F28: Light vehicle | J28: Mobile | K28: Active | L28: 3 | M28: 2 | N28: 2 | O28: 1 | P28: 1 | Q28: =IF(COUNT($L28:$P28)<5,"",ROUND(($L28*Lists!$M$2+$M28*Lists!$M$3+$N28*Lists!$M$4+$O28*Lists!$M$5+$P28*Lists!$M$6)/5*100,0)) -> 41 | R28: =IF($Q28="","",IF($Q28>=Lists!$M$20,"A",IF($Q28>=Lists!$M$21,"B","C"))) -> C | S28: =IF($A28="","",IF(COUNTIF(Records!$C$5:$C$3000,$A28)=0,"No data",CHOOSE(_xlfn.MAXIFS(Records!$R$5:$R$3000,Records!$C$5:$C$3000,$A28,Records!$Y$5:$Y$3000,"<>Closed")+1,"OK","Alert","Danger"))) -> OK | T28: =IF($A28="","",COUNTIFS(Records!$C$5:$C$3000,$A28,Records!$R$5:$R$3000,">0",Records!$Y$5:$Y$3000,"<>Closed")) -> 0 | V28: Y | Z28: Y | AG28: Y | AH28: Y | AI28: N | AK28: =IF($AJ28="","",$AJ28-TODAY()) | AL28: =IF($AJ28="","",IF($AK28<0,"Danger",IF($AK28<=Lists!$M$24,"Alert","OK"))) | AM28: Fleet workshop | AP28: 3 | AS28: 60000 | AT28: Default: criticality factors (safety and environment 3, production 2) | AU28: 2022 | AV28: 6
A29: 100601 | B29: HV-01 | C29: Dozer HV-01 | D29: Mobile fleet | E29: Heavy equipment | F29: Heavy equipment | J29: Mobile | K29: Active | L29: 4 | M29: 3 | N29: 3 | O29: 4 | P29: 3 | Q29: =IF(COUNT($L29:$P29)<5,"",ROUND(($L29*Lists!$M$2+$M29*Lists!$M$3+$N29*Lists!$M$4+$O29*Lists!$M$5+$P29*Lists!$M$6)/5*100,0)) -> 69 | R29: =IF($Q29="","",IF($Q29>=Lists!$M$20,"A",IF($Q29>=Lists!$M$21,"B","C"))) -> B | S29: =IF($A29="","",IF(COUNTIF(Records!$C$5:$C$3000,$A29)=0,"No data",CHOOSE(_xlfn.MAXIFS(Records!$R$5:$R$3000,Records!$C$5:$C$3000,$A29,Records!$Y$5:$Y$3000,"<>Closed")+1,"OK","Alert","Danger"))) -> Alert | T29: =IF($A29="","",COUNTIFS(Records!$C$5:$C$3000,$A29,Records!$R$5:$R$3000,">0",Records!$Y$5:$Y$3000,"<>Closed")) -> 1 | V29: Y | Z29: Y | AG29: Y | AH29: Y | AI29: N | AK29: =IF($AJ29="","",$AJ29-TODAY()) | AL29: =IF($AJ29="","",IF($AK29<0,"Danger",IF($AK29<=Lists!$M$24,"Alert","OK"))) | AM29: Fleet workshop | AP29: 4 | AS29: 900000 | AT29: Default: criticality factors (safety and environment 4, production 3) | AU29: 2015 | AV29: 12
A30: 100602 | B30: HV-02 | C30: Compactor HV-02 | D30: Mobile fleet | E30: Heavy equipment | F30: Heavy equipment | J30: Mobile | K30: Active | L30: 4 | M30: 2 | N30: 3 | O30: 3 | P30: 2 | Q30: =IF(COUNT($L30:$P30)<5,"",ROUND(($L30*Lists!$M$2+$M30*Lists!$M$3+$N30*Lists!$M$4+$O30*Lists!$M$5+$P30*Lists!$M$6)/5*100,0)) -> 58 | R30: =IF($Q30="","",IF($Q30>=Lists!$M$20,"A",IF($Q30>=Lists!$M$21,"B","C"))) -> B | S30: =IF($A30="","",IF(COUNTIF(Records!$C$5:$C$3000,$A30)=0,"No data",CHOOSE(_xlfn.MAXIFS(Records!$R$5:$R$3000,Records!$C$5:$C$3000,$A30,Records!$Y$5:$Y$3000,"<>Closed")+1,"OK","Alert","Danger"))) -> Danger | T30: =IF($A30="","",COUNTIFS(Records!$C$5:$C$3000,$A30,Records!$R$5:$R$3000,">0",Records!$Y$5:$Y$3000,"<>Closed")) -> 1 | V30: Y | Z30: Y | AG30: Y | AH30: Y | AI30: N | AK30: =IF($AJ30="","",$AJ30-TODAY()) | AL30: =IF($AJ30="","",IF($AK30<0,"Danger",IF($AK30<=Lists!$M$24,"Alert","OK"))) | AM30: Fleet workshop | AP30: 4 | AS30: 450000 | AT30: Default: criticality factors (safety and environment 4, production 2) | AU30: 2016 | AV30: 12
A31: 100603 | B31: HV-03 | C31: Front-end loader HV-03 | D31: Mobile fleet | E31: Heavy equipment | F31: Heavy equipment | J31: Mobile | K31: Active | L31: 4 | M31: 3 | N31: 3 | O31: 4 | P31: 2 | Q31: =IF(COUNT($L31:$P31)<5,"",ROUND(($L31*Lists!$M$2+$M31*Lists!$M$3+$N31*Lists!$M$4+$O31*Lists!$M$5+$P31*Lists!$M$6)/5*100,0)) -> 67 | R31: =IF($Q31="","",IF($Q31>=Lists!$M$20,"A",IF($Q31>=Lists!$M$21,"B","C"))) -> B | S31: =IF($A31="","",IF(COUNTIF(Records!$C$5:$C$3000,$A31)=0,"No data",CHOOSE(_xlfn.MAXIFS(Records!$R$5:$R$3000,Records!$C$5:$C$3000,$A31,Records!$Y$5:$Y$3000,"<>Closed")+1,"OK","Alert","Danger"))) -> Alert | T31: =IF($A31="","",COUNTIFS(Records!$C$5:$C$3000,$A31,Records!$R$5:$R$3000,">0",Records!$Y$5:$Y$3000,"<>Closed")) -> 1 | V31: Y | Z31: Y | AG31: Y | AH31: Y | AI31: N | AK31: =IF($AJ31="","",$AJ31-TODAY()) | AL31: =IF($AJ31="","",IF($AK31<0,"Danger",IF($AK31<=Lists!$M$24,"Alert","OK"))) | AM31: Fleet workshop | AP31: 4 | AS31: 700000 | AT31: Default: criticality factors (safety and environment 4, production 3) | AU31: 2017 | AV31: 12
Q32: =IF(COUNT($L32:$P32)<5,"",ROUND(($L32*Lists!$M$2+$M32*Lists!$M$3+$N32*Lists!$M$4+$O32*Lists!$M$5+$P32*Lists!$M$6)/5*100,0)) | R32: =IF($Q32="","",IF($Q32>=Lists!$M$20,"A",IF($Q32>=Lists!$M$21,"B","C"))) | S32: =IF($A32="","",IF(COUNTIF(Records!$C$5:$C$3000,$A32)=0,"No data",CHOOSE(_xlfn.MAXIFS(Records!$R$5:$R$3000,Records!$C$5:$C$3000,$A32,Records!$Y$5:$Y$3000,"<>Closed")+1,"OK","Alert","Danger"))) | T32: =IF($A32="","",COUNTIFS(Records!$C$5:$C$3000,$A32,Records!$R$5:$R$3000,">0",Records!$Y$5:$Y$3000,"<>Closed")) | AK32: =IF($AJ32="","",$AJ32-TODAY()) | AL32: =IF($AJ32="","",IF($AK32<0,"Danger",IF($AK32<=Lists!$M$24,"Alert","OK")))
Q33: =IF(COUNT($L33:$P33)<5,"",ROUND(($L33*Lists!$M$2+$M33*Lists!$M$3+$N33*Lists!$M$4+$O33*Lists!$M$5+$P33*Lists!$M$6)/5*100,0)) | R33: =IF($Q33="","",IF($Q33>=Lists!$M$20,"A",IF($Q33>=Lists!$M$21,"B","C"))) | S33: =IF($A33="","",IF(COUNTIF(Records!$C$5:$C$3000,$A33)=0,"No data",CHOOSE(_xlfn.MAXIFS(Records!$R$5:$R$3000,Records!$C$5:$C$3000,$A33,Records!$Y$5:$Y$3000,"<>Closed")+1,"OK","Alert","Danger"))) | T33: =IF($A33="","",COUNTIFS(Records!$C$5:$C$3000,$A33,Records!$R$5:$R$3000,">0",Records!$Y$5:$Y$3000,"<>Closed")) | AK33: =IF($AJ33="","",$AJ33-TODAY()) | AL33: =IF($AJ33="","",IF($AK33<0,"Danger",IF($AK33<=Lists!$M$24,"Alert","OK")))
Q34: =IF(COUNT($L34:$P34)<5,"",ROUND(($L34*Lists!$M$2+$M34*Lists!$M$3+$N34*Lists!$M$4+$O34*Lists!$M$5+$P34*Lists!$M$6)/5*100,0)) | R34: =IF($Q34="","",IF($Q34>=Lists!$M$20,"A",IF($Q34>=Lists!$M$21,"B","C"))) | S34: =IF($A34="","",IF(COUNTIF(Records!$C$5:$C$3000,$A34)=0,"No data",CHOOSE(_xlfn.MAXIFS(Records!$R$5:$R$3000,Records!$C$5:$C$3000,$A34,Records!$Y$5:$Y$3000,"<>Closed")+1,"OK","Alert","Danger"))) | T34: =IF($A34="","",COUNTIFS(Records!$C$5:$C$3000,$A34,Records!$R$5:$R$3000,">0",Records!$Y$5:$Y$3000,"<>Closed")) | AK34: =IF($AJ34="","",$AJ34-TODAY()) | AL34: =IF($AJ34="","",IF($AK34<0,"Danger",IF($AK34<=Lists!$M$24,"Alert","OK")))
Q35: =IF(COUNT($L35:$P35)<5,"",ROUND(($L35*Lists!$M$2+$M35*Lists!$M$3+$N35*Lists!$M$4+$O35*Lists!$M$5+$P35*Lists!$M$6)/5*100,0)) | R35: =IF($Q35="","",IF($Q35>=Lists!$M$20,"A",IF($Q35>=Lists!$M$21,"B","C"))) | S35: =IF($A35="","",IF(COUNTIF(Records!$C$5:$C$3000,$A35)=0,"No data",CHOOSE(_xlfn.MAXIFS(Records!$R$5:$R$3000,Records!$C$5:$C$3000,$A35,Records!$Y$5:$Y$3000,"<>Closed")+1,"OK","Alert","Danger"))) | T35: =IF($A35="","",COUNTIFS(Records!$C$5:$C$3000,$A35,Records!$R$5:$R$3000,">0",Records!$Y$5:$Y$3000,"<>Closed")) | AK35: =IF($AJ35="","",$AJ35-TODAY()) | AL35: =IF($AJ35="","",IF($AK35<0,"Danger",IF($AK35<=Lists!$M$24,"Alert","OK")))
Q36: =IF(COUNT($L36:$P36)<5,"",ROUND(($L36*Lists!$M$2+$M36*Lists!$M$3+$N36*Lists!$M$4+$O36*Lists!$M$5+$P36*Lists!$M$6)/5*100,0)) | R36: =IF($Q36="","",IF($Q36>=Lists!$M$20,"A",IF($Q36>=Lists!$M$21,"B","C"))) | S36: =IF($A36="","",IF(COUNTIF(Records!$C$5:$C$3000,$A36)=0,"No data",CHOOSE(_xlfn.MAXIFS(Records!$R$5:$R$3000,Records!$C$5:$C$3000,$A36,Records!$Y$5:$Y$3000,"<>Closed")+1,"OK","Alert","Danger"))) | T36: =IF($A36="","",COUNTIFS(Records!$C$5:$C$3000,$A36,Records!$R$5:$R$3000,">0",Records!$Y$5:$Y$3000,"<>Closed")) | AK36: =IF($AJ36="","",$AJ36-TODAY()) | AL36: =IF($AJ36="","",IF($AK36<0,"Danger",IF($AK36<=Lists!$M$24,"Alert","OK")))
Q37: =IF(COUNT($L37:$P37)<5,"",ROUND(($L37*Lists!$M$2+$M37*Lists!$M$3+$N37*Lists!$M$4+$O37*Lists!$M$5+$P37*Lists!$M$6)/5*100,0)) | R37: =IF($Q37="","",IF($Q37>=Lists!$M$20,"A",IF($Q37>=Lists!$M$21,"B","C"))) | S37: =IF($A37="","",IF(COUNTIF(Records!$C$5:$C$3000,$A37)=0,"No data",CHOOSE(_xlfn.MAXIFS(Records!$R$5:$R$3000,Records!$C$5:$C$3000,$A37,Records!$Y$5:$Y$3000,"<>Closed")+1,"OK","Alert","Danger"))) | T37: =IF($A37="","",COUNTIFS(Records!$C$5:$C$3000,$A37,Records!$R$5:$R$3000,">0",Records!$Y$5:$Y$3000,"<>Closed")) | AK37: =IF($AJ37="","",$AJ37-TODAY()) | AL37: =IF($AJ37="","",IF($AK37<0,"Danger",IF($AK37<=Lists!$M$24,"Alert","OK")))
Q38: =IF(COUNT($L38:$P38)<5,"",ROUND(($L38*Lists!$M$2+$M38*Lists!$M$3+$N38*Lists!$M$4+$O38*Lists!$M$5+$P38*Lists!$M$6)/5*100,0)) | R38: =IF($Q38="","",IF($Q38>=Lists!$M$20,"A",IF($Q38>=Lists!$M$21,"B","C"))) | S38: =IF($A38="","",IF(COUNTIF(Records!$C$5:$C$3000,$A38)=0,"No data",CHOOSE(_xlfn.MAXIFS(Records!$R$5:$R$3000,Records!$C$5:$C$3000,$A38,Records!$Y$5:$Y$3000,"<>Closed")+1,"OK","Alert","Danger"))) | T38: =IF($A38="","",COUNTIFS(Records!$C$5:$C$3000,$A38,Records!$R$5:$R$3000,">0",Records!$Y$5:$Y$3000,"<>Closed")) | AK38: =IF($AJ38="","",$AJ38-TODAY()) | AL38: =IF($AJ38="","",IF($AK38<0,"Danger",IF($AK38<=Lists!$M$24,"Alert","OK")))
Q39: =IF(COUNT($L39:$P39)<5,"",ROUND(($L39*Lists!$M$2+$M39*Lists!$M$3+$N39*Lists!$M$4+$O39*Lists!$M$5+$P39*Lists!$M$6)/5*100,0)) | R39: =IF($Q39="","",IF($Q39>=Lists!$M$20,"A",IF($Q39>=Lists!$M$21,"B","C"))) | S39: =IF($A39="","",IF(COUNTIF(Records!$C$5:$C$3000,$A39)=0,"No data",CHOOSE(_xlfn.MAXIFS(Records!$R$5:$R$3000,Records!$C$5:$C$3000,$A39,Records!$Y$5:$Y$3000,"<>Closed")+1,"OK","Alert","Danger"))) | T39: =IF($A39="","",COUNTIFS(Records!$C$5:$C$3000,$A39,Records!$R$5:$R$3000,">0",Records!$Y$5:$Y$3000,"<>Closed")) | AK39: =IF($AJ39="","",$AJ39-TODAY()) | AL39: =IF($AJ39="","",IF($AK39<0,"Danger",IF($AK39<=Lists!$M$24,"Alert","OK")))
Q40: =IF(COUNT($L40:$P40)<5,"",ROUND(($L40*Lists!$M$2+$M40*Lists!$M$3+$N40*Lists!$M$4+$O40*Lists!$M$5+$P40*Lists!$M$6)/5*100,0)) | R40: =IF($Q40="","",IF($Q40>=Lists!$M$20,"A",IF($Q40>=Lists!$M$21,"B","C"))) | S40: =IF($A40="","",IF(COUNTIF(Records!$C$5:$C$3000,$A40)=0,"No data",CHOOSE(_xlfn.MAXIFS(Records!$R$5:$R$3000,Records!$C$5:$C$3000,$A40,Records!$Y$5:$Y$3000,"<>Closed")+1,"OK","Alert","Danger"))) | T40: =IF($A40="","",COUNTIFS(Records!$C$5:$C$3000,$A40,Records!$R$5:$R$3000,">0",Records!$Y$5:$Y$3000,"<>Closed")) | AK40: =IF($AJ40="","",$AJ40-TODAY()) | AL40: =IF($AJ40="","",IF($AK40<0,"Danger",IF($AK40<=Lists!$M$24,"Alert","OK")))
...

Sheet Records
A1: AHIM Common Record
A2: One row per reading, checklist defect or certificate check, from ANY source. Dark headers = enter. Grey = automatic. Blue italic rows are SAMPLES showing each source: delete them before go-live.
A4: Record ID | B4: Date | C4: Pronto asset no. | D4: Description | E4: Area | F4: Class | G4: ACI | H4: Source (input) | I4: Technique | J4: Component / parameter / checklist item | K4: Value | L4: Unit | M4: Alert limit | N4: Danger limit | O4: Limit direction | P4: Inspector status | Q4: Status | R4: Severity | S4: Finding | T4: Recommendation | U4: Priority score | V4: Priority | W4: Due date | X4: Pronto WO no. | Y4: Record stage | Z4: Inspector | AA4: Date closed | AB4: Verified by | AC4: Days open | AD4: Due status | AE4: Remarks | AF4: Failure mode (ISO 14224) | AG4: Failure mechanism (ISO 14224) | AH4: Damage mechanism (API 571) | AI4: Execution window | AJ4: Likelihood override (1-5)
A5: =IF($C5="","","R"&TEXT(ROW()-4,"00000")) -> R00001 | B5: 45931 | C5: 100110 | D5: =IF($C5="","",IFERROR(INDEX(Asset_Register!$C$5:$C$1000,MATCH($C5,Asset_Register!$A$5:$A$1000,0)),"Not in register")) -> Molten sulphur pump | E5: =IF($C5="","",IFERROR(INDEX(Asset_Register!$D$5:$D$1000,MATCH($C5,Asset_Register!$A$5:$A$1000,0)),"Not in register")) -> Acid plant | F5: =IF($C5="","",IFERROR(INDEX(Asset_Register!$R$5:$R$1000,MATCH($C5,Asset_Register!$A$5:$A$1000,0)),"Not in register")) -> B | G5: =IF($C5="","",IFERROR(INDEX(Asset_Register!$Q$5:$Q$1000,MATCH($C5,Asset_Register!$A$5:$A$1000,0)),"Not in register")) -> 61 | H5: Vibration & visual route | I5: Vibration | J5: Overall velocity (max point) | K5: 2.4 | L5: mm/s | M5: 4.5 | N5: 7.1 | O5: Higher is worse | Q5: =IF($C5="","",IF($P5<>"",$P5,IF(AND(ISNUMBER($K5),ISNUMBER($M5),ISNUMBER($N5)),IF($O5="Lower is worse",IF($K5<=$N5,"Danger",IF($K5<=$M5,"Alert","OK")),IF($K5>=$N5,"Danger",IF($K5>=$M5,"Alert","OK"))),"Not set"))) -> OK | R5: =IF(OR($Q5="",$Q5="Not set"),"",MATCH($Q5,Lists!$F$2:$F$4,0)-1) -> 0 | U5: =IF(OR($Q5="",$Q5="OK",$Q5="Not set",NOT(ISNUMBER($G5))),"",ROUND($G5*IF($Q5="Danger",Lists!$M$15,Lists!$M$16),0)) | V5: =IF($U5="","",IF(OR($Q5="Danger",$U5>=Lists!$M$10),"P1",IF($U5>=Lists!$M$11,"P2","P3"))) | W5: =IF(OR($V5="",$B5=""),"",$B5+INDEX(Lists!$N$10:$N$12,MATCH($V5,Lists!$L$10:$L$12,0))) | Y5: No action | Z5: RCM Specialist | AC5: =IF(OR($U5="",$B5=""),"",IF($AA5<>"",$AA5-$B5,TODAY()-$B5)) | AD5: =IF($W5="","",IF($Y5="Closed",IF($AA5="","Closed",IF($AA5<=$W5,"Closed on time","Closed late")),IF(TODAY()>$W5,"Overdue","Within time")))
A6: =IF($C6="","","R"&TEXT(ROW()-4,"00000")) -> R00002 | B6: 45931 | C6: 100115 | D6: =IF($C6="","",IFERROR(INDEX(Asset_Register!$C$5:$C$1000,MATCH($C6,Asset_Register!$A$5:$A$1000,0)),"Not in register")) -> Instrument air receiver | E6: =IF($C6="","",IFERROR(INDEX(Asset_Register!$D$5:$D$1000,MATCH($C6,Asset_Register!$A$5:$A$1000,0)),"Not in register")) -> Acid plant | F6: =IF($C6="","",IFERROR(INDEX(Asset_Register!$R$5:$R$1000,MATCH($C6,Asset_Register!$A$5:$A$1000,0)),"Not in register")) -> B | G6: =IF($C6="","",IFERROR(INDEX(Asset_Register!$Q$5:$Q$1000,MATCH($C6,Asset_Register!$A$5:$A$1000,0)),"Not in register")) -> 53 | H6: Ultrasonic report | I6: Ultrasonics (airborne) | J6: Leak survey level | K6: 12 | L6: dBµV | M6: 30 | N6: 40 | O6: Higher is worse | Q6: =IF($C6="","",IF($P6<>"",$P6,IF(AND(ISNUMBER($K6),ISNUMBER($M6),ISNUMBER($N6)),IF($O6="Lower is worse",IF($K6<=$N6,"Danger",IF($K6<=$M6,"Alert","OK")),IF($K6>=$N6,"Danger",IF($K6>=$M6,"Alert","OK"))),"Not set"))) -> OK | R6: =IF(OR($Q6="",$Q6="Not set"),"",MATCH($Q6,Lists!$F$2:$F$4,0)-1) -> 0 | U6: =IF(OR($Q6="",$Q6="OK",$Q6="Not set",NOT(ISNUMBER($G6))),"",ROUND($G6*IF($Q6="Danger",Lists!$M$15,Lists!$M$16),0)) | V6: =IF($U6="","",IF(OR($Q6="Danger",$U6>=Lists!$M$10),"P1",IF($U6>=Lists!$M$11,"P2","P3"))) | W6: =IF(OR($V6="",$B6=""),"",$B6+INDEX(Lists!$N$10:$N$12,MATCH($V6,Lists!$L$10:$L$12,0))) | Y6: No action | Z6: RCM Specialist | AC6: =IF(OR($U6="",$B6=""),"",IF($AA6<>"",$AA6-$B6,TODAY()-$B6)) | AD6: =IF($W6="","",IF($Y6="Closed",IF($AA6="","Closed",IF($AA6<=$W6,"Closed on time","Closed late")),IF(TODAY()>$W6,"Overdue","Within time")))
A7: =IF($C7="","","R"&TEXT(ROW()-4,"00000")) -> R00003 | B7: 45932 | C7: 100108 | D7: =IF($C7="","",IFERROR(INDEX(Asset_Register!$C$5:$C$1000,MATCH($C7,Asset_Register!$A$5:$A$1000,0)),"Not in register")) -> Boiler feed water pump A | E7: =IF($C7="","",IFERROR(INDEX(Asset_Register!$D$5:$D$1000,MATCH($C7,Asset_Register!$A$5:$A$1000,0)),"Not in register")) -> Acid plant | F7: =IF($C7="","",IFERROR(INDEX(Asset_Register!$R$5:$R$1000,MATCH($C7,Asset_Register!$A$5:$A$1000,0)),"Not in register")) -> A | G7: =IF($C7="","",IFERROR(INDEX(Asset_Register!$Q$5:$Q$1000,MATCH($C7,Asset_Register!$A$5:$A$1000,0)),"Not in register")) -> 75 | H7: Vibration & visual route | I7: Vibration | J7: Overall velocity (max point) | K7: 2.5 | L7: mm/s | M7: 4.5 | N7: 7.1 | O7: Higher is worse | Q7: =IF($C7="","",IF($P7<>"",$P7,IF(AND(ISNUMBER($K7),ISNUMBER($M7),ISNUMBER($N7)),IF($O7="Lower is worse",IF($K7<=$N7,"Danger",IF($K7<=$M7,"Alert","OK")),IF($K7>=$N7,"Danger",IF($K7>=$M7,"Alert","OK"))),"Not set"))) -> OK | R7: =IF(OR($Q7="",$Q7="Not set"),"",MATCH($Q7,Lists!$F$2:$F$4,0)-1) -> 0 | U7: =IF(OR($Q7="",$Q7="OK",$Q7="Not set",NOT(ISNUMBER($G7))),"",ROUND($G7*IF($Q7="Danger",Lists!$M$15,Lists!$M$16),0)) | V7: =IF($U7="","",IF(OR($Q7="Danger",$U7>=Lists!$M$10),"P1",IF($U7>=Lists!$M$11,"P2","P3"))) | W7: =IF(OR($V7="",$B7=""),"",$B7+INDEX(Lists!$N$10:$N$12,MATCH($V7,Lists!$L$10:$L$12,0))) | Y7: No action | Z7: RCM Specialist | AC7: =IF(OR($U7="",$B7=""),"",IF($AA7<>"",$AA7-$B7,TODAY()-$B7)) | AD7: =IF($W7="","",IF($Y7="Closed",IF($AA7="","Closed",IF($AA7<=$W7,"Closed on time","Closed late")),IF(TODAY()>$W7,"Overdue","Within time")))
A8: =IF($C8="","","R"&TEXT(ROW()-4,"00000")) -> R00004 | B8: 45932 | C8: 100111 | D8: =IF($C8="","",IFERROR(INDEX(Asset_Register!$C$5:$C$1000,MATCH($C8,Asset_Register!$A$5:$A$1000,0)),"Not in register")) -> Sulphur melter agitator | E8: =IF($C8="","",IFERROR(INDEX(Asset_Register!$D$5:$D$1000,MATCH($C8,Asset_Register!$A$5:$A$1000,0)),"Not in register")) -> Acid plant | F8: =IF($C8="","",IFERROR(INDEX(Asset_Register!$R$5:$R$1000,MATCH($C8,Asset_Register!$A$5:$A$1000,0)),"Not in register")) -> C | G8: =IF($C8="","",IFERROR(INDEX(Asset_Register!$Q$5:$Q$1000,MATCH($C8,Asset_Register!$A$5:$A$1000,0)),"Not in register")) -> 43 | H8: Vibration & visual route | I8: Vibration | J8: Overall velocity (max point) | K8: 1.4 | L8: mm/s | M8: 4.5 | N8: 7.1 | O8: Higher is worse | Q8: =IF($C8="","",IF($P8<>"",$P8,IF(AND(ISNUMBER($K8),ISNUMBER($M8),ISNUMBER($N8)),IF($O8="Lower is worse",IF($K8<=$N8,"Danger",IF($K8<=$M8,"Alert","OK")),IF($K8>=$N8,"Danger",IF($K8>=$M8,"Alert","OK"))),"Not set"))) -> OK | R8: =IF(OR($Q8="",$Q8="Not set"),"",MATCH($Q8,Lists!$F$2:$F$4,0)-1) -> 0 | U8: =IF(OR($Q8="",$Q8="OK",$Q8="Not set",NOT(ISNUMBER($G8))),"",ROUND($G8*IF($Q8="Danger",Lists!$M$15,Lists!$M$16),0)) | V8: =IF($U8="","",IF(OR($Q8="Danger",$U8>=Lists!$M$10),"P1",IF($U8>=Lists!$M$11,"P2","P3"))) | W8: =IF(OR($V8="",$B8=""),"",$B8+INDEX(Lists!$N$10:$N$12,MATCH($V8,Lists!$L$10:$L$12,0))) | Y8: No action | Z8: RCM Specialist | AC8: =IF(OR($U8="",$B8=""),"",IF($AA8<>"",$AA8-$B8,TODAY()-$B8)) | AD8: =IF($W8="","",IF($Y8="Closed",IF($AA8="","Closed",IF($AA8<=$W8,"Closed on time","Closed late")),IF(TODAY()>$W8,"Overdue","Within time")))
A9: =IF($C9="","","R"&TEXT(ROW()-4,"00000")) -> R00005 | B9: 45935 | C9: 100109 | D9: =IF($C9="","",IFERROR(INDEX(Asset_Register!$C$5:$C$1000,MATCH($C9,Asset_Register!$A$5:$A$1000,0)),"Not in register")) -> Boiler feed water pump B | E9: =IF($C9="","",IFERROR(INDEX(Asset_Register!$D$5:$D$1000,MATCH($C9,Asset_Register!$A$5:$A$1000,0)),"Not in register")) -> Acid plant | F9: =IF($C9="","",IFERROR(INDEX(Asset_Register!$R$5:$R$1000,MATCH($C9,Asset_Register!$A$5:$A$1000,0)),"Not in register")) -> A | G9: =IF($C9="","",IFERROR(INDEX(Asset_Register!$Q$5:$Q$1000,MATCH($C9,Asset_Register!$A$5:$A$1000,0)),"Not in register")) -> 71 | H9: Vibration & visual route | I9: Vibration | J9: Overall velocity (max point) | K9: 1.8 | L9: mm/s | M9: 4.5 | N9: 7.1 | O9: Higher is worse | Q9: =IF($C9="","",IF($P9<>"",$P9,IF(AND(ISNUMBER($K9),ISNUMBER($M9),ISNUMBER($N9)),IF($O9="Lower is worse",IF($K9<=$N9,"Danger",IF($K9<=$M9,"Alert","OK")),IF($K9>=$N9,"Danger",IF($K9>=$M9,"Alert","OK"))),"Not set"))) -> OK | R9: =IF(OR($Q9="",$Q9="Not set"),"",MATCH($Q9,Lists!$F$2:$F$4,0)-1) -> 0 | U9: =IF(OR($Q9="",$Q9="OK",$Q9="Not set",NOT(ISNUMBER($G9))),"",ROUND($G9*IF($Q9="Danger",Lists!$M$15,Lists!$M$16),0)) | V9: =IF($U9="","",IF(OR($Q9="Danger",$U9>=Lists!$M$10),"P1",IF($U9>=Lists!$M$11,"P2","P3"))) | W9: =IF(OR($V9="",$B9=""),"",$B9+INDEX(Lists!$N$10:$N$12,MATCH($V9,Lists!$L$10:$L$12,0))) | Y9: No action | Z9: RCM Specialist | AC9: =IF(OR($U9="",$B9=""),"",IF($AA9<>"",$AA9-$B9,TODAY()-$B9)) | AD9: =IF($W9="","",IF($Y9="Closed",IF($AA9="","Closed",IF($AA9<=$W9,"Closed on time","Closed late")),IF(TODAY()>$W9,"Overdue","Within time")))
A10: =IF($C10="","","R"&TEXT(ROW()-4,"00000")) -> R00006 | B10: 45935 | C10: 100108 | D10: =IF($C10="","",IFERROR(INDEX(Asset_Register!$C$5:$C$1000,MATCH($C10,Asset_Register!$A$5:$A$1000,0)),"Not in register")) -> Boiler feed water pump A | E10: =IF($C10="","",IFERROR(INDEX(Asset_Register!$D$5:$D$1000,MATCH($C10,Asset_Register!$A$5:$A$1000,0)),"Not in register")) -> Acid plant | F10: =IF($C10="","",IFERROR(INDEX(Asset_Register!$R$5:$R$1000,MATCH($C10,Asset_Register!$A$5:$A$1000,0)),"Not in register")) -> A | G10: =IF($C10="","",IFERROR(INDEX(Asset_Register!$Q$5:$Q$1000,MATCH($C10,Asset_Register!$A$5:$A$1000,0)),"Not in register")) -> 75 | H10: Oil analysis | I10: Lubrication / oil | J10: Water in bearing oil | K10: 150 | L10: ppm | M10: 1000 | N10: 2000 | O10: Higher is worse | Q10: =IF($C10="","",IF($P10<>"",$P10,IF(AND(ISNUMBER($K10),ISNUMBER($M10),ISNUMBER($N10)),IF($O10="Lower is worse",IF($K10<=$N10,"Danger",IF($K10<=$M10,"Alert","OK")),IF($K10>=$N10,"Danger",IF($K10>=$M10,"Alert","OK"))),"Not set"))) -> OK | R10: =IF(OR($Q10="",$Q10="Not set"),"",MATCH($Q10,Lists!$F$2:$F$4,0)-1) -> 0 | U10: =IF(OR($Q10="",$Q10="OK",$Q10="Not set",NOT(ISNUMBER($G10))),"",ROUND($G10*IF($Q10="Danger",Lists!$M$15,Lists!$M$16),0)) | V10: =IF($U10="","",IF(OR($Q10="Danger",$U10>=Lists!$M$10),"P1",IF($U10>=Lists!$M$11,"P2","P3"))) | W10: =IF(OR($V10="",$B10=""),"",$B10+INDEX(Lists!$N$10:$N$12,MATCH($V10,Lists!$L$10:$L$12,0))) | Y10: No action | Z10: RCM Specialist | AC10: =IF(OR($U10="",$B10=""),"",IF($AA10<>"",$AA10-$B10,TODAY()-$B10)) | AD10: =IF($W10="","",IF($Y10="Closed",IF($AA10="","Closed",IF($AA10<=$W10,"Closed on time","Closed late")),IF(TODAY()>$W10,"Overdue","Within time")))
A11: =IF($C11="","","R"&TEXT(ROW()-4,"00000")) -> R00007 | B11: 45938 | C11: 100101 | D11: =IF($C11="","",IFERROR(INDEX(Asset_Register!$C$5:$C$1000,MATCH($C11,Asset_Register!$A$5:$A$1000,0)),"Not in register")) -> Sulphur furnace | E11: =IF($C11="","",IFERROR(INDEX(Asset_Register!$D$5:$D$1000,MATCH($C11,Asset_Register!$A$5:$A$1000,0)),"Not in register")) -> Acid plant | F11: =IF($C11="","",IFERROR(INDEX(Asset_Register!$R$5:$R$1000,MATCH($C11,Asset_Register!$A$5:$A$1000,0)),"Not in register")) -> A | G11: =IF($C11="","",IFERROR(INDEX(Asset_Register!$Q$5:$Q$1000,MATCH($C11,Asset_Register!$A$5:$A$1000,0)),"Not in register")) -> 94 | H11: IR survey | I11: Infrared | J11: Burner-end shell temperature | K11: 210 | L11: °C | M11: 280 | N11: 320 | O11: Higher is worse | Q11: =IF($C11="","",IF($P11<>"",$P11,IF(AND(ISNUMBER($K11),ISNUMBER($M11),ISNUMBER($N11)),IF($O11="Lower is worse",IF($K11<=$N11,"Danger",IF($K11<=$M11,"Alert","OK")),IF($K11>=$N11,"Danger",IF($K11>=$M11,"Alert","OK"))),"Not set"))) -> OK | R11: =IF(OR($Q11="",$Q11="Not set"),"",MATCH($Q11,Lists!$F$2:$F$4,0)-1) -> 0 | U11: =IF(OR($Q11="",$Q11="OK",$Q11="Not set",NOT(ISNUMBER($G11))),"",ROUND($G11*IF($Q11="Danger",Lists!$M$15,Lists!$M$16),0)) | V11: =IF($U11="","",IF(OR($Q11="Danger",$U11>=Lists!$M$10),"P1",IF($U11>=Lists!$M$11,"P2","P3"))) | W11: =IF(OR($V11="",$B11=""),"",$B11+INDEX(Lists!$N$10:$N$12,MATCH($V11,Lists!$L$10:$L$12,0))) | Y11: No action | Z11: RCM Specialist | AC11: =IF(OR($U11="",$B11=""),"",IF($AA11<>"",$AA11-$B11,TODAY()-$B11)) | AD11: =IF($W11="","",IF($Y11="Closed",IF($AA11="","Closed",IF($AA11<=$W11,"Closed on time","Closed late")),IF(TODAY()>$W11,"Overdue","Within time")))
A12: =IF($C12="","","R"&TEXT(ROW()-4,"00000")) -> R00008 | B12: 45940 | C12: 100112 | D12: =IF($C12="","",IFERROR(INDEX(Asset_Register!$C$5:$C$1000,MATCH($C12,Asset_Register!$A$5:$A$1000,0)),"Not in register")) -> Cooling tower fan 1 | E12: =IF($C12="","",IFERROR(INDEX(Asset_Register!$D$5:$D$1000,MATCH($C12,Asset_Register!$A$5:$A$1000,0)),"Not in register")) -> Acid plant | F12: =IF($C12="","",IFERROR(INDEX(Asset_Register!$R$5:$R$1000,MATCH($C12,Asset_Register!$A$5:$A$1000,0)),"Not in register")) -> B | G12: =IF($C12="","",IFERROR(INDEX(Asset_Register!$Q$5:$Q$1000,MATCH($C12,Asset_Register!$A$5:$A$1000,0)),"Not in register")) -> 50 | H12: Vibration & visual route | I12: Vibration | J12: Gearbox overall velocity | K12: 3.2 | L12: mm/s | M12: 4.5 | N12: 7.1 | O12: Higher is worse | Q12: =IF($C12="","",IF($P12<>"",$P12,IF(AND(ISNUMBER($K12),ISNUMBER($M12),ISNUMBER($N12)),IF($O12="Lower is worse",IF($K12<=$N12,"Danger",IF($K12<=$M12,"Alert","OK")),IF($K12>=$N12,"Danger",IF($K12>=$M12,"Alert","OK"))),"Not set"))) -> OK | R12: =IF(OR($Q12="",$Q12="Not set"),"",MATCH($Q12,Lists!$F$2:$F$4,0)-1) -> 0 | U12: =IF(OR($Q12="",$Q12="OK",$Q12="Not set",NOT(ISNUMBER($G12))),"",ROUND($G12*IF($Q12="Danger",Lists!$M$15,Lists!$M$16),0)) | V12: =IF($U12="","",IF(OR($Q12="Danger",$U12>=Lists!$M$10),"P1",IF($U12>=Lists!$M$11,"P2","P3"))) | W12: =IF(OR($V12="",$B12=""),"",$B12+INDEX(Lists!$N$10:$N$12,MATCH($V12,Lists!$L$10:$L$12,0))) | Y12: No action | Z12: RCM Specialist | AC12: =IF(OR($U12="",$B12=""),"",IF($AA12<>"",$AA12-$B12,TODAY()-$B12)) | AD12: =IF($W12="","",IF($Y12="Closed",IF($AA12="","Closed",IF($AA12<=$W12,"Closed on time","Closed late")),IF(TODAY()>$W12,"Overdue","Within time")))
A13: =IF($C13="","","R"&TEXT(ROW()-4,"00000")) -> R00009 | B13: 45940 | C13: 100201 | D13: =IF($C13="","",IFERROR(INDEX(Asset_Register!$C$5:$C$1000,MATCH($C13,Asset_Register!$A$5:$A$1000,0)),"Not in register")) -> Calciner kiln 1080 | E13: =IF($C13="","",IFERROR(INDEX(Asset_Register!$D$5:$D$1000,MATCH($C13,Asset_Register!$A$5:$A$1000,0)),"Not in register")) -> Calciner | F13: =IF($C13="","",IFERROR(INDEX(Asset_Register!$R$5:$R$1000,MATCH($C13,Asset_Register!$A$5:$A$1000,0)),"Not in register")) -> A | G13: =IF($C13="","",IFERROR(INDEX(Asset_Register!$Q$5:$Q$1000,MATCH($C13,Asset_Register!$A$5:$A$1000,0)),"Not in register")) -> 90 | H13: IR survey | I13: Infrared | J13: Zone 4 shell temperature | K13: 240 | L13: °C | M13: 280 | N13: 350 | O13: Higher is worse | Q13: =IF($C13="","",IF($P13<>"",$P13,IF(AND(ISNUMBER($K13),ISNUMBER($M13),ISNUMBER($N13)),IF($O13="Lower is worse",IF($K13<=$N13,"Danger",IF($K13<=$M13,"Alert","OK")),IF($K13>=$N13,"Danger",IF($K13>=$M13,"Alert","OK"))),"Not set"))) -> OK | R13: =IF(OR($Q13="",$Q13="Not set"),"",MATCH($Q13,Lists!$F$2:$F$4,0)-1) -> 0 | U13: =IF(OR($Q13="",$Q13="OK",$Q13="Not set",NOT(ISNUMBER($G13))),"",ROUND($G13*IF($Q13="Danger",Lists!$M$15,Lists!$M$16),0)) | V13: =IF($U13="","",IF(OR($Q13="Danger",$U13>=Lists!$M$10),"P1",IF($U13>=Lists!$M$11,"P2","P3"))) | W13: =IF(OR($V13="",$B13=""),"",$B13+INDEX(Lists!$N$10:$N$12,MATCH($V13,Lists!$L$10:$L$12,0))) | Y13: No action | Z13: RCM Specialist | AC13: =IF(OR($U13="",$B13=""),"",IF($AA13<>"",$AA13-$B13,TODAY()-$B13)) | AD13: =IF($W13="","",IF($Y13="Closed",IF($AA13="","Closed",IF($AA13<=$W13,"Closed on time","Closed late")),IF(TODAY()>$W13,"Overdue","Within time")))
A14: =IF($C14="","","R"&TEXT(ROW()-4,"00000")) -> R00010 | B14: 45940 | C14: 100112 | D14: =IF($C14="","",IFERROR(INDEX(Asset_Register!$C$5:$C$1000,MATCH($C14,Asset_Register!$A$5:$A$1000,0)),"Not in register")) -> Cooling tower fan 1 | E14: =IF($C14="","",IFERROR(INDEX(Asset_Register!$D$5:$D$1000,MATCH($C14,Asset_Register!$A$5:$A$1000,0)),"Not in register")) -> Acid plant | F14: =IF($C14="","",IFERROR(INDEX(Asset_Register!$R$5:$R$1000,MATCH($C14,Asset_Register!$A$5:$A$1000,0)),"Not in register")) -> B | G14: =IF($C14="","",IFERROR(INDEX(Asset_Register!$Q$5:$Q$1000,MATCH($C14,Asset_Register!$A$5:$A$1000,0)),"Not in register")) -> 50 | H14: Oil analysis | I14: Lubrication / oil | J14: Copper (Cu) in gearbox oil | K14: 10 | L14: ppm | M14: 30 | N14: 60 | O14: Higher is worse | Q14: =IF($C14="","",IF($P14<>"",$P14,IF(AND(ISNUMBER($K14),ISNUMBER($M14),ISNUMBER($N14)),IF($O14="Lower is worse",IF($K14<=$N14,"Danger",IF($K14<=$M14,"Alert","OK")),IF($K14>=$N14,"Danger",IF($K14>=$M14,"Alert","OK"))),"Not set"))) -> OK | R14: =IF(OR($Q14="",$Q14="Not set"),"",MATCH($Q14,Lists!$F$2:$F$4,0)-1) -> 0 | U14: =IF(OR($Q14="",$Q14="OK",$Q14="Not set",NOT(ISNUMBER($G14))),"",ROUND($G14*IF($Q14="Danger",Lists!$M$15,Lists!$M$16),0)) | V14: =IF($U14="","",IF(OR($Q14="Danger",$U14>=Lists!$M$10),"P1",IF($U14>=Lists!$M$11,"P2","P3"))) | W14: =IF(OR($V14="",$B14=""),"",$B14+INDEX(Lists!$N$10:$N$12,MATCH($V14,Lists!$L$10:$L$12,0))) | Y14: No action | Z14: RCM Specialist | AC14: =IF(OR($U14="",$B14=""),"",IF($AA14<>"",$AA14-$B14,TODAY()-$B14)) | AD14: =IF($W14="","",IF($Y14="Closed",IF($AA14="","Closed",IF($AA14<=$W14,"Closed on time","Closed late")),IF(TODAY()>$W14,"Overdue","Within time")))
